Workbook

Sheet Perakende
A1: AĞUSTOS KURGU | F1: 45504
A2: AĞUSTOS KURGU 31.07 (PERAKENDE) | D2: TEMMUZ TOPTAN | E2: TEMMUZ PERAKENDE | F2: YS STOK | G2: STOK+ FİKTİF | I2: Temmuz Max Potansiyeli | J2: Temmuz Perakende Öngörüsü | K2: Ağustos Devir | M2: 3 Haziran 2024 LİSTE FİYATI | N2: 3 Haziran 2024 KAMPANYALI FİYAT | P2: 1 Temmuz 2024 LİSTE FİYATI | Q2: 1 Temmuz 2024 KAMPANYALI FİYAT | R2: PLANLANAN LİSTE FİYAT DEĞİŞİMİ | S2: 1 Temmuz 2024 KAMPANYALI FİYAT DEĞİŞİMİ | T2: KREDİ KAMPANYALARI | V2: KALAN TEMMUZ GELİŞ | W2: KALAN TEMMUZ GELİŞ | X2: KALAN AĞUSTOS GELİŞ | Y2: TOPLAM AĞUSTOS GELİŞ | AA2: AĞUSTOS MAX PERAKENDE POTANSİYELİ | AB2: AĞUSTOS Satış Öngörü | AC2: EYLÜL DEVİR | AD2: EYLÜL TAHMİNİ GELİŞ | AE2: EYLÜL MAX POTANSİYEL
A4: FABIA | B4: Fabia Elite 1,0 TSI 95 PS | F4: =#REF!+#REF! -> #REF! | G4: 0 | I4: =H4+G4 -> 0 | R4: =P4/M4-1 -> #DIV/0! | S4: =Q4/N4-1 -> #DIV/0! | AA4: =Y4+F4+G4 -> #REF! | AC4: =AA4-AB4 -> #REF!
B5: Yeni Fabia Premium 1,0 TSI 115 PS DSG | D5: 188 | E5: 128 | F5: 62 | G5: 22 | I5: =SUM(G5,F5,E5) -> 212 | K5: =I5-J5 -> 212 | M5: 1329900 | N5: 1206700 | P5: 1329900 | Q5: 1239100 | R5: =P5/M5-1 -> 0 | S5: =Q5/N5-1 -> 0.026850087 | T5: 150.000 12 Ay 0,99 | X5: 155 | Y5: =SUM(V5:X5) -> 155 | AA5: =Y5+K5 -> 367 | AC5: =AA5-AB5 -> 367 | AE5: =AD5+AC5 -> 367
B6: Yeni Fabia Monte Carlo 1,5 TSI 150 PS DSG | D6: 18 | E6: 7 | F6: 17 | G6: 2 | I6: =SUM(G6,F6,E6) -> 26 | K6: =I6-J6 -> 26 | M6: 1569900 | N6: 1416700 | P6: 1569900 | Q6: 1462700 | R6: =P6/M6-1 -> 0 | S6: =Q6/N6-1 -> 0.032469824 | X6: 6 | Y6: =SUM(V6:X6) -> 6 | AA6: =Y6+K6 -> 32 | AC6: =AA6-AB6 -> 32 | AE6: =AD6+AC6 -> 32
B7: Diğer | I7: =SUM(G7,F7,E7) -> 0 | K7: =I7-J7 -> 0 | X7: 0 | Y7: =SUM(V7:X7) -> 0 | AA7: =Y7+K7 -> 0 | AC7: =AA7-AB7 -> 0 | AE7: =AD7+AC7 -> 0
B8: FABIA TOPLAM | D8: =SUM(D4:D7) -> 206 | E8: =SUM(E4:E7) -> 135 | F8: =SUM(F5:F7) -> 79 | G8: =SUM(G5:G7) -> 24 | I8: =SUM(I4:I7) -> 238 | J8: =SUM(J4:J7) -> 0 | K8: =SUM(K4:K7) -> 238 | V8: =SUM(V4:V7) -> 0 | W8: =SUM(W4:W7) -> 0 | X8: =SUM(X4:X7) -> 161 | Y8: =SUM(Y4:Y7) -> 161 | AA8: =SUM(AA5:AA7) -> 399 | AB8: =SUM(AB4:AB7) -> 0 | AC8: =SUM(AC5:AC7) -> 399 | AD8: =SUM(AD4:AD7) -> 0 | AE8: =SUM(AE4:AE7) -> 399
A10: SCALA | B10: Yeni Scala Elite 1,0 TSI 115 PS DSG | D10: 31 | E10: 17 | F10: 37 | G10: 7 | I10: =SUM(G10,F10,E10) -> 61 | K10: =I10-J10 -> 61 | M10: 1439900 | N10: 1282500 | P10: 1439900 | Q10: 1316300 | R10: =P10/M10-1 -> 0 | S10: =Q10/N10-1 -> 0.026354776 | T10: 150.000 12 Ay 0,99 | X10: 10 | Y10: =SUM(V10:X10) -> 10 | AA10: =Y10+K10 -> 71 | AC10: =AA10-AB10 -> 71 | AE10: =AD10+AC10 -> 71
B11: Yeni Scala Premium 1,0 TSI 115 PS DSG | D11: 2 | E11: 1 | F11: 2 | I11: =SUM(G11,F11,E11) -> 3 | K11: =I11-J11 -> 3 | M11: 1619900 | N11: 1413500 | P11: 1619900 | Q11: 1435700 | R11: =P11/M11-1 -> 0 | S11: =Q11/N11-1 -> 0.015705695 | X11: 9 | Y11: =SUM(V11:X11) -> 9 | AA11: =Y11+K11 -> 12 | AC11: =AA11-AB11 -> 12 | AE11: =AD11+AC11 -> 12
B12: Yeni Scala Premium 1,5 TSI 150 PS DSG | D12: 42 | E12: 29 | F12: 24 | G12: 6 | I12: =SUM(G12,F12,E12) -> 59 | K12: =I12-J12 -> 59 | M12: 1689900 | N12: 1474700 | P12: 1689900 | Q12: 1498000 | R12: =P12/M12-1 -> 0 | S12: =Q12/N12-1 -> 0.015799824 | Y12: =SUM(V12:X12) -> 0 | AA12: =Y12+K12 -> 59 | AC12: =AA12-AB12 -> 59 | AE12: =AD12+AC12 -> 59
B13: Yeni Scala Monte Carlo 1,5 TSI 150 PS DSG | D13: 28 | E13: 17 | F13: 19 | G13: 15 | I13: =SUM(G13,F13,E13) -> 51 | K13: =I13-J13 -> 51 | M13: 1849900 | N13: 1591200 | P13: 1849900 | Q13: 1591200 | R13: =P13/M13-1 -> 0 | S13: =Q13/N13-1 -> 0 | X13: 24 | Y13: =SUM(V13:X13) -> 24 | AA13: =Y13+K13 -> 75 | AC13: =AA13-AB13 -> 75 | AE13: =AD13+AC13 -> 75
B14: Diğer | E14: 2 | I14: =SUM(G14,F14,E14) -> 2 | K14: =I14-J14 -> 2 | Y14: =SUM(V14:X14) -> 0 | AA14: =Y14+K14 -> 2 | AC14: =AA14-AB14 -> 2 | AE14: =AD14+AC14 -> 2
B15: SCALA TOPLAM | D15: =SUM(D10:D14) -> 103 | E15: =SUM(E10:E14) -> 66 | F15: =SUM(F10:F14) -> 82 | G15: =SUM(G10:G14) -> 28 | I15: =SUM(I10:I14) -> 176 | J15: =SUM(J10:J14) -> 0 | K15: =SUM(K10:K14) -> 176 | V15: =SUM(V10:V14) -> 0 | W15: =SUM(W10:W14) -> 0 | X15: =SUM(X10:X14) -> 43 | Y15: =SUM(Y10:Y14) -> 43 | AA15: =SUM(AA10:AA14) -> 219 | AB15: =SUM(AB10:AB14) -> 0 | AC15: =SUM(AC10:AC14) -> 219 | AD15: =SUM(AD10:AD14) -> 0 | AE15: =SUM(AE10:AE14) -> 219
A17: KAMIQ | B17: Yeni Kamiq Elite 1,0 TSI 115 PS DSG | D17: 408 | E17: 265 | F17: 173 | G17: 18 | I17: =SUM(G17,F17,E17) -> 456 | K17: =I17-J17 -> 456 | M17: 1539900 | N17: 1328700 | P17: 1539900 | Q17: 1393300 | R17: =P17/M17-1 -> 0 | S17: =Q17/N17-1 -> 0.048618951 | T17: 150.000 12 Ay 0% | X17: 40 | Y17: =SUM(V17:X17) -> 40 | AA17: =Y17+K17 -> 496 | AC17: =AA17-AB17 -> 496 | AE17: =AD17+AC17 -> 496
B18: Yeni Kamiq Premium 1,0 TSI 115 PS DSG | D18: 107 | E18: 55 | F18: 56 | G18: 24 | I18: =SUM(G18,F18,E18) -> 135 | K18: =I18-J18 -> 135 | M18: 1719900 | N18: 1415800 | P18: 1719900 | Q18: 1485000 | R18: =P18/M18-1 -> 0 | S18: =Q18/N18-1 -> 0.04887696 | X18: 283 | Y18: =SUM(V18:X18) -> 283 | AA18: =Y18+K18 -> 418 | AC18: =AA18-AB18 -> 418 | AE18: =AD18+AC18 -> 418
B19: Yeni Kamiq Premium 1,5 TSI 150 PS DSG | D19: 60 | E19: 19 | F19: 42 | G19: 7 | I19: =SUM(G19,F19,E19) -> 68 | K19: =I19-J19 -> 68 | M19: 1809900 | N19: 1577600 | P19: 1809900 | Q19: 1602300 | R19: =P19/M19-1 -> 0 | S19: =Q19/N19-1 -> 0.015656694 | X19: 84 | Y19: =SUM(V19:X19) -> 84 | AA19: =Y19+K19 -> 152 | AC19: =AA19-AB19 -> 152 | AE19: =AD19+AC19 -> 152
B20: Yeni Kamiq Monte Carlo 1,5 TSI 150 PS DSG | D20: 45 | E20: 35 | F20: 24 | G20: 7 | I20: =SUM(G20,F20,E20) -> 66 | K20: =I20-J20 -> 66 | M20: 1999900 | N20: 1699700 | P20: 1999900 | Q20: 1754200 | R20: =P20/M20-1 -> 0 | S20: =Q20/N20-1 -> 0.032064482 | X20: 30 | Y20: =SUM(V20:X20) -> 30 | AA20: =Y20+K20 -> 96 | AC20: =AA20-AB20 -> 96 | AE20: =AD20+AC20 -> 96
B21: Diğer | E21: 1 | F21: 1 | I21: =SUM(G21,F21,E21) -> 2 | K21: =I21-J21 -> 2 | Y21: =SUM(V21:X21) -> 0 | AA21: =Y21+K21 -> 2 | AC21: =AA21-AB21 -> 2 | AE21: =AD21+AC21 -> 2
B22: KAMIQ TOPLAM | D22: =SUM(D17:D21) -> 620 | E22: =SUM(E17:E21) -> 375 | F22: =SUM(F17:F21) -> 296 | G22: =SUM(G17:G21) -> 56 | I22: =SUM(I17:I21) -> 727 | J22: =SUM(J17:J21) -> 0 | K22: =SUM(K17:K21) -> 727 | V22: =SUM(V17:V21) -> 0 | W22: =SUM(W17:W21) -> 0 | X22: =SUM(X17:X21) -> 437 | Y22: =SUM(Y17:Y21) -> 437 | AA22: =SUM(AA17:AA21) -> 1164 | AB22: =SUM(AB17:AB21) -> 0 | AC22: =SUM(AC17:AC21) -> 1164 | AD22: =SUM(AD17:AD21) -> 0 | AE22: =SUM(AE17:AE21) -> 1164
A24: KAROQ | B24: Karoq Premium 1,5 TSI ACT 150 PS DSG (Yeni) | D24: 206 | E24: 307 | F24: 78 | G24: 14 | I24: =SUM(G24,F24,E24) -> 399 | K24: =I24-J24 -> 399 | M24: 2009900 | N24: 1981600 | P24: 2009900 | Q24: 1827000 | R24: =IFERROR(P24/M24-1,0) -> 0 | S24: =IFERROR(Q24/N24-1,0) -> -0.078017763 | T24: 250.000 TL 0 Faiz | X24: 69 | Y24: =SUM(V24:X24) -> 69 | AA24: =Y24+K24 -> 468 | AC24: =AA24-AB24 -> 468 | AE24: =AD24+AC24 -> 468
B25: Karoq Prestige 1,5 TSI ACT 150 PS DSG (Yeni) | D25: 76 | E25: 79 | F25: 40 | G25: 4 | I25: =SUM(G25,F25,E25) -> 123 | K25: =I25-J25 -> 123 | M25: 2159900 | N25: 2117700 | P25: 2159900 | Q25: 2000000 | R25: =IFERROR(P25/M25-1,0) -> 0 | S25: =IFERROR(Q25/N25-1,0) -> -0.055579166 | X25: 1 | Y25: =SUM(V25:X25) -> 1 | AA25: =Y25+K25 -> 124 | AC25: =AA25-AB25 -> 124 | AE25: =AD25+AC25 -> 124
B26: Karoq Sportline 1,5 TSI ACT 150 PS DSG (Yeni) | D26: 68 | E26: 81 | F26: 102 | G26: 1 | I26: =SUM(G26,F26,E26) -> 184 | K26: =I26-J26 -> 184 | M26: 2249900 | N26: 2206000 | P26: 2249900 | Q26: 2170000 | R26: =IFERROR(P26/M26-1,0) -> 0 | S26: =IFERROR(Q26/N26-1,0) -> -0.01631913 | T26: Tüzel Müşteri Kredi | Y26: =SUM(V26:X26) -> 0 | AA26: =Y26+K26 -> 184 | AC26: =AA26-AB26 -> 184 | AE26: =AD26+AC26 -> 184
B27: Diğer (Eski Karoq) | E27: 12 | F27: 5 | I27: =SUM(G27,F27,E27) -> 17 | K27: =I27-J27 -> 17 | AA27: =Y27+K27 -> 17 | AC27: =AA27-AB27 -> 17
B28: KAROQ TOPLAM | D28: =SUM(D24:D27) -> 350 | E28: =SUM(E24:E27) -> 479 | F28: =SUM(F24:F27) -> 225 | G28: =SUM(G24:G27) -> 19 | I28: =SUM(I24:I27) -> 723 | J28: =SUM(J24:J27) -> 0 | K28: =SUM(K24:K27) -> 723 | V28: =SUM(V24:V26) -> 0 | W28: =SUM(W24:W26) -> 0 | X28: =SUM(X24:X26) -> 70 | Y28: =SUM(Y24:Y26) -> 70 | AA28: =SUM(AA24:AA27) -> 793 | AB28: =SUM(AB24:AB26) -> 0 | AC28: =SUM(AC24:AC27) -> 793 | AD28: =SUM(AD24:AD26) -> 0 | AE28: =SUM(AE24:AE26) -> 776
A30: KODIAQ | B30: Kodiaq Prestige 1,5 TSI ACT 150 PS DSG | D30: 1 | F30: 14 | I30: =SUM(G30,F30,E30) -> 14 | K30: =I30-J30 -> 14 | M30: 2679900 | N30: 2370800 | P30: 2679900 | Q30: 2370800 | R30: =P30/M30-1 -> 0 | S30: =Q30/N30-1 -> 0 | T30: Tüzel 500.000 TL 12 Ay 1,99% | Y30: =SUM(V30:X30) -> 0 | AA30: =Y30+K30 -> 14 | AC30: =AA30-AB30 -> 14 | AE30: =AD30+AC30 -> 14
B31: Kodiaq Sportline 1,5 TSI ACT 150 PS DSG | I31: =SUM(G31,F31,E31) -> 0 | K31: =I31-J31 -> 0 | M31: 2739900 | N31: 2423900 | P31: 2739900 | Q31: 2423900 | R31: =P31/M31-1 -> 0 | S31: =Q31/N31-1 -> 0 | Y31: =SUM(V31:X31) -> 0 | AA31: =Y31+K31 -> 0 | AC31: =AA31-AB31 -> 0 | AE31: =AD31+AC31 -> 0
B32: Yeni Kodiaq Premium 1,5 TSI mHEV 150 PS DSG | D32: 69 | E32: 3 | F32: 66 | G32: 1 | I32: =SUM(G32,F32,E32) -> 70 | K32: =I32-J32 -> 70 | X32: 1 | Y32: =SUM(V32:X32) -> 1 | AA32: =Y32+K32 -> 71 | AC32: =AA32-AB32 -> 71 | AE32: =AD32+AC32 -> 71
B33: Yeni Kodiaq Prestige 1,5 TSI mHEV 150 PS DSG | D33: 323 | E33: 45 | F33: 278 | G33: 45 | I33: =SUM(G33,F33,E33) -> 368 | K33: =I33-J33 -> 368 | X33: 131 | Y33: =SUM(V33:X33) -> 131 | AA33: =Y33+K33 -> 499 | AC33: =AA33-AB33 -> 499 | AE33: =AD33+AC33 -> 499
B34: Diğer | E34: 30 | I34: =SUM(G34,F34,E34) -> 30 | K34: =I34-J34 -> 30 | Y34: =SUM(V34:X34) -> 0 | AA34: =Y34+K34 -> 30 | AC34: =AA34-AB34 -> 30 | AE34: =AD34+AC34 -> 30
B35: KODIAQ TOPLAM | D35: =SUM(D30:D34) -> 393 | E35: =SUM(E30:E34) -> 78 | F35: =SUM(F30:F34) -> 358 | G35: =SUM(G30:G34) -> 46 | I35: =SUM(I30:I34) -> 482 | J35: =SUM(J30:J34) -> 0 | K35: =SUM(K30:K34) -> 482 | V35: =SUM(V30:V34) -> 0 | W35: =SUM(W30:W34) -> 0 | X35: =SUM(X30:X34) -> 132 | Y35: =SUM(Y30:Y34) -> 132 | AA35: =SUM(AA30:AA34) -> 614 | AB35: =SUM(AB30:AB34) -> 0 | AC35: =SUM(AC30:AC34) -> 614 | AD35: =SUM(AD30:AD34) -> 0 | AE35: =SUM(AE30:AE34) -> 614
A37: OCTAVIA | B37: Octavia Elite 1,0 TSI E-Tec 110 PS DSG | D37: 19 | E37: 89 | F37: 15 | G37: 10 | I37: =SUM(G37,F37,E37) -> 114 | K37: =I37-J37 -> 114 | M37: 1544900 | N37: 1544900 | P37: 1544900 | Q37: 1544900 | R37: =P37/M37-1 -> 0 | S37: =Q37/N37-1 -> 0 | T37: 200.000 TL 12 Ay 0% | Y37: =SUM(V37:X37) -> 0 | AA37: =Y37+K37 -> 114 | AC37: =AA37-AB37 -> 114 | AE37: =AD37+AC37 -> 114
B38: Octavia Elite 1,5 TSI E-Tec 150 PS DSG | D38: 3 | E38: 1 | F38: 2 | I38: =SUM(G38,F38,E38) -> 3 | K38: =I38-J38 -> 3 | M38: 1646900 | N38: 1646900 | P38: 1646900 | Q38: 1646900 | R38: =P38/M38-1 -> 0 | S38: =Q38/N38-1 -> 0 | Y38: =SUM(V38:X38) -> 0 | AA38: =Y38+K38 -> 3 | AC38: =AA38-AB38 -> 3 | AE38: =AD38+AC38 -> 3
B39: Octavia Premium 1,0 TSI E-Tec 110 PS DSG | I39: =SUM(G39,F39,E39) -> 0 | K39: =I39-J39 -> 0 | M39: 1732900 | N39: 1732900 | P39: 1732900 | Q39: 1732900 | R39: =P39/M39-1 -> 0 | S39: =Q39/N39-1 -> 0 | Y39: =SUM(V39:X39) -> 0 | AA39: =Y39+K39 -> 0 | AC39: =AA39-AB39 -> 0 | AE39: =AD39+AC39 -> 0
B40: Octavia Premium 1,5 TSI E-Tec 150 PS DSG | D40: 6 | E40: 10 | F40: 27 | G40: 6 | I40: =SUM(G40,F40,E40) -> 43 | K40: =I40-J40 -> 43 | M40: 1834900 | N40: 1834900 | P40: 1834900 | Q40: 1834900 | R40: =P40/M40-1 -> 0 | S40: =Q40/N40-1 -> 0 | Y40: =SUM(V40:X40) -> 0 | AA40: =Y40+K40 -> 43 | AC40: =AA40-AB40 -> 43 | AE40: =AD40+AC40 -> 43
B41: Yeni Octavia Premium 1,5 TSI mHEV 150 PS DSG | D41: 231 | E41: 125 | F41: 106 | G41: 247 | I41: =SUM(G41,F41,E41) -> 478 | K41: =I41-J41 -> 478 | X41: 207 | Y41: =SUM(V41:X41) -> 207 | AA41: =Y41+K41 -> 685 | AC41: =AA41-AB41 -> 685 | AE41: =AD41+AC41 -> 685
B42: Diğer | E42: 1 | I42: =SUM(G42,F42,E42) -> 1 | K42: =I42-J42 -> 1 | Y42: =SUM(V42:X42) -> 0 | AA42: =Y42+K42 -> 1 | AC42: =AA42-AB42 -> 1 | AE42: =AD42+AC42 -> 1
B43: OCTAVIA TOPLAM | D43: =SUM(D37:D42) -> 259 | E43: =SUM(E37:E42) -> 226 | F43: =SUM(F37:F42) -> 150 | G43: =SUM(G37:G42) -> 263 | I43: =SUM(I37:I42) -> 639 | J43: =SUM(J37:J42) -> 0 | K43: =SUM(K37:K42) -> 639 | V43: =SUM(V37:V42) -> 0 | W43: =SUM(W37:W42) -> 0 | X43: =SUM(X37:X42) -> 207 | Y43: =SUM(Y37:Y42) -> 207 | AA43: =SUM(AA37:AA42) -> 846 | AB43: =SUM(AB37:AB42) -> 0 | AC43: =SUM(AC37:AC42) -> 846 | AD43: =SUM(AD37:AD42) -> 0 | AE43: =SUM(AE37:AE42) -> 846
A45: SUPERB | B45: Yeni Superb Elite 1,5 TSI mHEV 150 PS DSG | D45: 57 | E45: 84 | F45: 59 | I45: =SUM(G45,F45,E45) -> 143 | K45: =I45-J45 -> 143 | M45: 2049899.6 | N45: 1989900 | P45: 2049899.6 | Q45: 1989900 | R45: =P45/M45-1 -> 0 | S45: =Q45/N45-1 -> 0 | X45: 17 | Y45: =SUM(V45:X45) -> 17 | AA45: =Y45+K45 -> 160 | AC45: =AA45-AB45 -> 160 | AE45: =AD45+AC45 -> 160
B46: Yeni Superb Premium 1,5 TSI mHEV 150 PS DSG | D46: 4 | E46: 83 | F46: 76 | G46: 1 | I46: =SUM(G46,F46,E46) -> 160 | K46: =I46-J46 -> 160 | M46: 2299900.4 | N46: 2187600 | P46: 2299900.4 | Q46: 2250000 | R46: =P46/M46-1 -> 0 | S46: =Q46/N46-1 -> 0.02852441 | X46: 21 | Y46: =SUM(V46:X46) -> 21 | AA46: =Y46+K46 -> 181 | AC46: =AA46-AB46 -> 181 | AE46: =AD46+AC46 -> 181
B47: Yeni Superb Prestige 1,5 TSI mHEV 150 PS DSG | D47: 583 | E47: 235 | F47: 559 | G47: 48 | I47: =SUM(G47,F47,E47) -> 842 | K47: =I47-J47 -> 842 | M47: 2649900.2 | N47: 2494500 | P47: 2649900.2 | Q47: 2546300 | R47: =P47/M47-1 -> 0 | S47: =Q47/N47-1 -> 0.020765685 | X47: 83 | Y47: =SUM(V47:X47) -> 83 | AA47: =Y47+K47 -> 925 | AC47: =AA47-AB47 -> 925 | AE47: =AD47+AC47 -> 925
...

Sheet Kurgu
A1: {BU_AY} KURGU {TARİH} | D1: {BU_AY} TOPTAN | E1: {BU_AY} PERAKENDE | F1: YS STOK | G1: STOK+ FİKTİF | I1: {BU_AY} GELİŞ | J1: {BU_AY} MAX POTANSİYELİ | K1: {BU_AY} PERAKENDE ÖNGÖRÜSÜ | L1: {BU_AY} DEVİR | N1: =Perakende!M2 -> 3 Haziran 2024 LİSTE FİYATI | O1: =Perakende!N2 -> 3 Haziran 2024 KAMPANYALI FİYAT | P1: 1 NİSAN 2023 FİLO FİYAT | R1: =Perakende!P2 -> 1 Temmuz 2024 LİSTE FİYATI | S1: =Perakende!Q2 -> 1 Temmuz 2024 KAMPANYALI FİYAT | T1: =Perakende!#REF! -> #REF! | U1: =Perakende!#REF! -> #REF! | V1: PLANLANAN LİSTE FİYAT DEĞİŞİMİ | W1: =Perakende!S2 -> 1 Temmuz 2024 KAMPANYALI FİYAT DEĞİŞİMİ | X1: YETKİLİ SATICI DERİNLİK
N2: =Perakende!M4+#REF! -> #REF! | O2: =Perakende!N4+#REF! -> #REF! | V2: - | W2: -
N3: =Perakende!M5+#REF! -> #REF! | O3: =Perakende!N5+#REF! -> #REF! | V3: - | W3: -
N4: =Perakende!M6+#REF! -> #REF! | O4: =Perakende!N6+#REF! -> #REF! | V4: - | W4: -
N5: =Perakende!M7+#REF! -> #REF! | O5: =Perakende!N7+#REF! -> #REF! | V5: - | W5: -
N6: =Perakende!M8+#REF! -> #REF! | O6: =Perakende!N8+#REF! -> #REF! | V6: - | W6: -
N7: =Perakende!M9+#REF! -> #REF! | O7: =Perakende!N9+#REF! -> #REF! | V7: - | W7: -
N8: =Perakende!M10+#REF! -> #REF! | O8: =Perakende!N10+#REF! -> #REF! | V8: - | W8: -
N9: =Perakende!M11+#REF! -> #REF! | O9: =Perakende!N11+#REF! -> #REF! | V9: - | W9: -
N10: =Perakende!M12+#REF! -> #REF! | O10: =Perakende!N12+#REF! -> #REF! | V10: - | W10: -
N11: =Perakende!M13+#REF! -> #REF! | O11: =Perakende!N13+#REF! -> #REF! | V11: - | W11: -
N12: =Perakende!M14+#REF! -> #REF! | O12: =Perakende!N14+#REF! -> #REF! | V12: - | W12: -
N13: =Perakende!M15+#REF! -> #REF! | O13: =Perakende!N15+#REF! -> #REF! | V13: - | W13: -
... N18: =Perakende!M20+#REF! -> #REF! | O18: =Perakende!N20+#REF! -> #REF! | V18: - | W18: -
A19: - | B19: Fabia Toplam
A20: -
A35: - | B35: Scala Toplam
A36: -
A53: - | B53: Octavia Toplam
A54: -
A69: - | B69: Superb Toplam
A70: -
A81: - | B81: Kamiq Toplam
A82: -
A97: - | B97: Karoq Toplam
A98: -
A110: - | B110: Kodiaq Toplam
A111: - | B111: GENEL TOPLAM

Sheet Orijinal
A1: AĞUSTOS KURGU | D1: Mavi (sorgu) | F1: Turuncu (formül)
B2: Word sorgu no | D2: 1 | E2: 2 | F2: 3 | G2: 4 | M2: Burdaki tüm kolonlar tutulmalıdır. Başlıkları exceli export eden kişi düzeltecektir. | AB2: 5
B3: Olması Gereken Sütun İsimleri | D3: Toptan Satış | E3: Perakende Satış | F3: YS Stok | G3: Stok+Fiktif | I3: İlgili Ay Maksimum Potansiyel | J3: İlgili Ay Perakende Öngörüsü | K3: Bir sonraki ay adı + devir | AB3: bir sonraki ay geliş | AD3: bir sonraki ay max potansiyel | AE3: bir sonraki ay öngörü | AF3: 2 sonraki ay devir
A4: AĞUSTOS KURGU 31.07 (FİLO) | D4: Temmuz TOPTAN | E4: Temmuz PERAKENDE | F4: YS STOK | G4: STOK+ FİKTİF | I4: Temmuz Max Potansiyeli | J4: Temmuz Perakende Öngörüsü | K4: Ağustos Devir | M4: =Perakende!M2 -> 3 Haziran 2024 LİSTE FİYATI | N4: =Perakende!N2 -> 3 Haziran 2024 KAMPANYALI FİYAT | O4: 1 NİSAN 2023 FİLO FİYAT | Q4: =Perakende!P2 -> 1 Temmuz 2024 LİSTE FİYATI | R4: =Perakende!Q2 -> 1 Temmuz 2024 KAMPANYALI FİYAT | S4: =Perakende!#REF! -> #REF! | T4: =Perakende!#REF! -> #REF! | U4: PLANLANAN LİSTE FİYAT DEĞİŞİMİ | V4: =Perakende!S2 -> 1 Temmuz 2024 KAMPANYALI FİYAT DEĞİŞİMİ | W4: YETKİLİ SATICI DERİNLİK | Y4: TEMMUZ KALAN GELİŞ | Z4: TEMMUZ KALAN GELİŞ | AA4: AĞUSTOS KALAN GELİŞ | AB4: TOPLAM AĞUSTOS GELİŞ | AD4: AĞUSTOS MAX PERAKENDE POTANSİYELİ | AE4: AĞUSOTS Satış Öngörü | AF4: AĞUSTOS DEVİR
A6: FABIA | B6: Fabia Elite 1,0 TSI 95 PS | I6: =H6+G6 -> 0 | J6: =E6 -> 0 | K6: =J6+I6 -> 0 | M6: =Perakende!M4+$Q$1 -> 0 | N6: =Perakende!N4+$Q$1 -> 0 | U6: - | V6: - | AD6: =AB6+F6+G6 -> 0 | AF6: =AD6-AE6 -> 0
B7: Fabia Elite 1,0 TSI 110 PS DSG | I7: =H7+G7 -> 0 | J7: =E7 -> 0 | K7: =J7+I7 -> 0 | M7: =Perakende!M5+$Q$1 -> 1329900 | N7: =Perakende!N5+$Q$1 -> 1206700 | U7: - | V7: - | AD7: =AB7+F7+G7 -> 0 | AF7: =AD7-AE7 -> 0
B8: Fabia Premium 1,0 TSI 110 PS DSG | I8: =H8+G8 -> 0 | J8: =E8 -> 0 | K8: =J8+I8 -> 0 | M8: =Perakende!M6+$Q$1 -> 1569900 | N8: =Perakende!N6+$Q$1 -> 1416700 | U8: - | V8: - | AD8: =AB8+F8+G8 -> 0 | AF8: =AD8-AE8 -> 0
B9: Fabia Premium 1,0 TSI 115 PS DSG (Yeni) | I9: =H9+G9 -> 0 | J9: =E9 -> 0 | K9: =J9+I9 -> 0 | M9: =Perakende!M7+$Q$1 -> 0 | N9: =Perakende!N7+$Q$1 -> 0 | U9: - | V9: - | AD9: =AB9+F9+G9 -> 0 | AF9: =AD9-AE9 -> 0
B10: Fabia Monte Carlo 1,5 TSI 150 PS DSG | I10: =H10+G10 -> 0 | J10: =E10 -> 0 | K10: =J10+I10 -> 0 | M10: =Perakende!M8+$Q$1 -> 0 | N10: =Perakende!N8+$Q$1 -> 0 | U10: - | V10: - | AD10: =AB10+F10+G10 -> 0 | AF10: =AD10-AE10 -> 0
B11: Fabia Monte Carlo 1,5 TSI 150 PS DSG (Yeni) | I11: =H11+G11 -> 0 | J11: =E11 -> 0 | K11: =J11+I11 -> 0 | AD11: =AB11+F11+G11 -> 0 | AF11: =AD11-AE11 -> 0
B12: FABIA TOPLAM | D12: =SUM(D6:D11) -> 0 | E12: =SUM(E6:E11) -> 0 | F12: =SUM(F6:F11) -> 0 | G12: =SUM(G6:G11) -> 0 | I12: =SUM(I6:I11) -> 0 | J12: =SUM(J6:J11) -> 0 | K12: =SUM(K6:K11) -> 0 | Y12: =SUM(Y6:Y11) -> 0 | Z12: =SUM(Z6:Z11) -> 0 | AA12: =SUM(AA6:AA11) -> 0 | AB12: =SUM(AB6:AB11) -> 0 | AD12: =SUM(AD6:AD11) -> 0 | AE12: =SUM(AE6:AE11) -> 0 | AF12: =SUM(AF6:AF11) -> 0
A14: SCALA | B14: Scala Elite 1,0 TSI 110 PS DSG | I14: =G14+F14+E14 -> 0 | J14: =E14 -> 0 | K14: =I14-J14 -> 0 | AA14: 70 | AD14: =AB14+K14 -> 0 | AF14: =AD14-AE14 -> 0
B15: Scala Premium 1,0 TSI 110 PS DSG | I15: =G15+F15+E15 -> 0 | J15: =E15 -> 0 | K15: =I15-J15 -> 0 | AA15: 71 | AD15: =AB15+K15 -> 0 | AF15: =AD15-AE15 -> 0
B16: Scala Premium 1,5 TSI ACT 150 PS DSG | I16: =G16+F16+E16 -> 0 | J16: =E16 -> 0 | K16: =I16-J16 -> 0 | AA16: 72 | AD16: =AB16+K16 -> 0 | AF16: =AD16-AE16 -> 0
B17: Yeni Scala Elite 1,0 TSI 115 PS DSG | I17: =G17+F17+E17 -> 0 | J17: =E17 -> 0 | K17: =I17-J17 -> 0 | AA17: 1 | AD17: =AB17+K17 -> 0 | AF17: =AD17-AE17 -> 0
B18: Yeni Scala Premium 1,5 TSI 150 PS DSG | I18: =G18+F18+E18 -> 0 | J18: =E18 -> 0 | K18: =I18-J18 -> 0 | AD18: =AB18+K18 -> 0 | AF18: =AD18-AE18 -> 0
B19: Yeni Scala Premium 1,0 TSI 115 PS DSG | I19: =G19+F19+E19 -> 0 | J19: =E19 -> 0 | K19: =I19-J19 -> 0 | AD19: =AB19+K19 -> 0 | AF19: =AD19-AE19 -> 0
B20: Yeni Scala Monte Carlo 1,5 TSI 150 PS DSG | I20: =G20+F20+E20 -> 0 | J20: =E20 -> 0 | K20: =I20-J20 -> 0 | AD20: =AB20+K20 -> 0 | AF20: =AD20-AE20 -> 0
B21: SCALA TOPLAM | D21: =SUM(D14:D20) -> 0 | E21: =SUM(E14:E20) -> 0 | F21: =SUM(F14:F20) -> 0 | G21: =SUM(G14:G20) -> 0 | I21: =SUM(I14:I20) -> 0 | J21: =SUM(J14:J20) -> 0 | K21: =SUM(K14:K20) -> 0 | Y21: =SUM(Y14:Y20) -> 0 | Z21: =SUM(Z14:Z20) -> 0 | AA21: =SUM(AA14:AA20) -> 214 | AB21: =SUM(AB14:AB20) -> 0 | AD21: =SUM(AD14:AD20) -> 0 | AE21: =SUM(AE14:AE20) -> 0 | AF21: =SUM(AF14:AF20) -> 0
A23: KAMIQ | B23: Kamiq Elite 1,0 TSI 110 PS DSG | I23: =G23+F23+E23 -> 0 | J23: =E23 -> 0 | K23: =I23-J23 -> 0 | AA23: 2 | AD23: =AB23+K23 -> 0 | AF23: =AD23-AE23 -> 0
B24: Kamiq Premium 1,5 TSI ACT 150 PS DSG | I24: =G24+F24+E24 -> 0 | J24: =E24 -> 0 | K24: =I24-J24 -> 0 | AA24: 3 | AD24: =AB24+K24 -> 0 | AF24: =AD24-AE24 -> 0
B25: Yeni Kamiq Elite 1,0 TSI 115 PS DSG | I25: =G25+F25+E25 -> 0 | J25: =E25 -> 0 | K25: =I25-J25 -> 0 | AA25: 4 | AD25: =AB25+K25 -> 0 | AF25: =AD25-AE25 -> 0
B26: Yeni Kamiq Premium 1,0 TSI 115 PS DSG | I26: =G26+F26+E26 -> 0 | J26: =E26 -> 0 | K26: =I26-J26 -> 0 | AA26: 5 | AD26: =AB26+K26 -> 0 | AF26: =AD26-AE26 -> 0
B27: Yeni Kamiq Premium 1,5 TSI 150 PS DSG | I27: =G27+F27+E27 -> 0 | J27: =E27 -> 0 | K27: =I27-J27 -> 0 | AD27: =AB27+K27 -> 0 | AF27: =AD27-AE27 -> 0
B28: Yeni Kamiq Monte Carlo 1,5 TSI 150 PS DSG | I28: =G28+F28+E28 -> 0 | J28: =E28 -> 0 | K28: =I28-J28 -> 0 | AD28: =AB28+K28 -> 0 | AF28: =AD28-AE28 -> 0
B29: KAMIQ TOPLAM | D29: =SUM(D23:D27) -> 0 | E29: =SUM(E23:E27) -> 0 | F29: =SUM(F23:F27) -> 0 | G29: =SUM(G23:G28) -> 0 | I29: =SUM(I23:I28) -> 0 | J29: =SUM(J23:J28) -> 0 | K29: =SUM(K23:K28) -> 0 | Y29: =SUM(Y23:Y28) -> 0 | Z29: =SUM(Z23:Z28) -> 0 | AA29: =SUM(AA23:AA28) -> 14 | AB29: =SUM(AB23:AB28) -> 0 | AD29: =SUM(AD23:AD28) -> 0 | AE29: =SUM(AE23:AE28) -> 0 | AF29: =SUM(AF23:AF28) -> 0
A31: KAROQ | B31: Karoq Elite 1,5 TSI ACT 150 PS DSG | I31: =G31+F31+E31 -> 0 | J31: =E31 -> 0 | K31: =I31-J31 -> 0 | AB31: =SUM(Y31:AA31) -> 0 | AD31: =AB31+K31 -> 0 | AF31: =AD31-AE31 -> 0
B32: Karoq Prestige 1,5 TSI ACT 150 PS DSG | I32: =G32+F32+E32 -> 0 | J32: =E32 -> 0 | K32: =I32-J32 -> 0 | AB32: =SUM(Y32:AA32) -> 0 | AD32: =AB32+K32 -> 0 | AF32: =AD32-AE32 -> 0
B33: Karoq Sportline 1,5 TSI ACT 150 PS DSG | I33: =G33+F33+E33 -> 0 | J33: =E33 -> 0 | K33: =I33-J33 -> 0 | AB33: =SUM(Y33:AA33) -> 0 | AD33: =AB33+K33 -> 0 | AF33: =AD33-AE33 -> 0
B34: Karoq Premium 1,5 TSI ACT 150 PS DSG (Yeni) | I34: =G34+F34+E34 -> 0 | J34: =E34 -> 0 | K34: =I34-J34 -> 0 | AB34: =SUM(Y34:AA34) -> 0 | AD34: =AB34+K34 -> 0 | AF34: =AD34-AE34 -> 0
B35: Karoq Prestige 1,5 TSI ACT 150 PS DSG (Yeni) | I35: =G35+F35+E35 -> 0 | J35: =E35 -> 0 | K35: =I35-J35 -> 0 | AB35: =SUM(Y35:AA35) -> 0 | AD35: =AB35+K35 -> 0 | AF35: =AD35-AE35 -> 0
B36: Karoq Sportline 1,5 TSI ACT 150 PS DSG (Yeni) | I36: =G36+F36+E36 -> 0 | J36: =E36 -> 0 | K36: =I36-J36 -> 0 | AB36: =SUM(Y36:AA36) -> 0 | AD36: =AB36+K36 -> 0 | AF36: =AD36-AE36 -> 0
B37: KAROQ TOPLAM | D37: =SUM(D31:D36) -> 0 | E37: =SUM(E31:E36) -> 0 | F37: =SUM(F31:F36) -> 0 | G37: =SUM(G31:G36) -> 0 | I37: =SUM(I31:I36) -> 0 | J37: =SUM(J31:J36) -> 0 | K37: =SUM(K31:K36) -> 0 | Y37: =SUM(Y31:Y36) -> 0 | Z37: =SUM(Z31:Z36) -> 0 | AA37: =SUM(AA31:AA36) -> 0 | AB37: =SUM(AB31:AB36) -> 0 | AD37: =SUM(AD31:AD36) -> 0 | AE37: =SUM(AE31:AE36) -> 0 | AF37: =SUM(AF31:AF36) -> 0
A39: KODIAQ | B39: Kodiaq Elite 1,5 TSI ACT 150 PS DSG | I39: =H39+G39 -> 0 | J39: =E39 -> 0 | K39: =J39+I39 -> 0 | AB39: =SUM(Y39:AA39) -> 0 | AD39: =AB39+G39+F39+E39 -> 0 | AF39: =AD39-AE39 -> 0
B40: Kodiaq Premium 1,5 TSI ACT 150 PS DSG | I40: =H40+G40 -> 0 | J40: =E40 -> 0 | K40: =J40+I40 -> 0 | AB40: =SUM(Y40:AA40) -> 0 | AD40: =AB40+G40+F40+E40 -> 0 | AF40: =AD40-AE40 -> 0
B41: Kodiaq Prestige 1,5 TSI ACT 150 PS DSG | I41: =H41+G41 -> 0 | J41: =E41 -> 0 | K41: =J41+I41 -> 0 | AB41: =SUM(Y41:AA41) -> 0 | AD41: =AB41+G41+F41+E41 -> 0 | AF41: =AD41-AE41 -> 0
B42: Kodiaq Sportline 1,5 TSI ACT 150 PS DSG | I42: =H42+G42 -> 0 | J42: =E42 -> 0 | K42: =J42+I42 -> 0 | AB42: =SUM(Y42:AA42) -> 0 | AD42: =AB42+G42+F42+E42 -> 0 | AF42: =AD42-AE42 -> 0
B43: Kodiaq Sportline 2,0 TDI SCR 200 PS DSG 4x4 | I43: =H43+G43 -> 0 | J43: =E43 -> 0 | K43: =J43+I43 -> 0 | AB43: =SUM(Y43:AA43) -> 0 | AD43: =AB43+G43+F43+E43 -> 0 | AF43: =AD43-AE43 -> 0
B44: Kodiaq Laurin & Klement Crystal 2,0 TDI SCR 200 PS DSG 4x4 | I44: =H44+G44 -> 0 | J44: =E44 -> 0 | K44: =J44+I44 -> 0 | AB44: =SUM(Y44:AA44) -> 0 | AD44: =AB44+G44+F44+E44 -> 0 | AF44: =AD44-AE44 -> 0
B45: Yeni Kodiaq Premium 1,5 TSI mHEV 150 PS DSG | I45: =H45+G45 -> 0 | J45: =E45 -> 0 | K45: =J45+I45 -> 0 | AB45: =SUM(Y45:AA45) -> 0 | AD45: =AB45+G45+F45+E45 -> 0 | AF45: =AD45-AE45 -> 0
...

Sheet Filo versiyon bazlı detay
B2: Toptan | I2: YS Stok
B3: Kodiaq | C3: Kodiaq Prestige 1,5 TSI ACT 150 PS DSG | D3: 9 | I3: Octavia | J3: Octavia Elite 1,0 TSI E-Tec 110 PS DSG | K3: 6
B4: Octavia | C4: Octavia Elite 1,0 TSI E-Tec 110 PS DSG | D4: 130 | I4: Octavia | J4: Octavia Premium 1,5 TSI E-Tec 150 PS DSG | K4: 2
B5: Octavia | C5: Octavia Elite 1,5 TSI E-Tec 150 PS DSG | D5: 1 | I5: Octavia | J5: Octavia Prestige 1,5 TSI E-Tec 150 PS DSG | K5: 3
B6: Octavia | C6: Octavia Premium 1,5 TSI E-Tec 150 PS DSG | D6: 3 | I6: Scala | J6: Yeni Scala Elite 1,0 TSI 115 PS DSG | K6: 1
B7: Octavia | C7: Octavia Prestige 1,5 TSI E-Tec 150 PS DSG | D7: 50 | I7: Yeni Octavia | J7: Yeni Octavia Premium 1,5 TSI mHEV 150 PS DSG | K7: 15
B8: Scala | C8: Yeni Scala Elite 1,0 TSI 115 PS DSG | D8: 61 | I8: Yeni Superb | J8: Superb (Diğer) | K8: 6
B9: Yeni Octavia | C9: Yeni Octavia Premium 1,5 TSI mHEV 150 PS DSG | D9: 130 | I9: Yeni Superb | J9: Yeni Superb Premium 1,5 TSI mHEV 150 PS DSG | K9: 26
B10: Yeni Superb | C10: Superb (Diğer) | D10: 65 | I10: Yeni Superb | J10: Yeni Superb Prestige 1,5 TSI mHEV 150 PS DSG | K10: 28
B11: Yeni Superb | C11: Yeni Superb Laurin & Klement Crystal 1,5 TSI mHEV 150 PS DSG | D11: 63
B12: Yeni Superb | C12: Yeni Superb Premium 1,5 TSI mHEV 150 PS DSG | D12: 311
B13: Yeni Superb | C13: Yeni Superb Prestige 1,5 TSI mHEV 150 PS DSG | D13: 228
I14: Stok Fiktif
B15: Perakende | I15: Kodiaq | J15: Kodiaq Prestige 1,5 TSI ACT 150 PS DSG | K15: 5
B16: Fabia | C16: Fabia Premium 1,0 TSI 115 PS DSG (Yeni) | D16: 1 | I16: Octavia | J16: Octavia Elite 1,0 TSI E-Tec 110 PS DSG | K16: 57
B17: Kamiq | C17: Yeni Kamiq Elite 1,0 TSI 115 PS DSG | D17: 5 | I17: Octavia | J17: Octavia Elite 1,5 TSI E-Tec 150 PS DSG | K17: 5
B18: Karoq | C18: Karoq Prestige 1,5 TSI ACT 150 PS DSG (Yeni) | D18: 3 | I18: Octavia | J18: Octavia Premium 1,0 TSI E-Tec 110 PS DSG | K18: 1
B19: Kodiaq | C19: Kodiaq Prestige 1,5 TSI ACT 150 PS DSG | D19: 10 | I19: Octavia | J19: Octavia Premium 1,5 TSI E-Tec 150 PS DSG | K19: 18
B20: Octavia | C20: Octavia Elite 1,0 TSI E-Tec 110 PS DSG | D20: 143 | I20: Octavia | J20: Octavia Prestige 1,5 TSI E-Tec 150 PS DSG | K20: 47
B21: Octavia | C21: Octavia Elite 1,5 TSI E-Tec 150 PS DSG | D21: 1 | I21: Scala | J21: Scala Premium 1,0 TSI 110 PS DSG | K21: 4
B22: Octavia | C22: Octavia Premium 1,5 TSI E-Tec 150 PS DSG | D22: 4 | I22: Scala | J22: Yeni Scala Elite 1,0 TSI 115 PS DSG | K22: 130
B23: Octavia | C23: Octavia Prestige 1,5 TSI E-Tec 150 PS DSG | D23: 47 | I23: Yeni Kodiaq | J23: Yeni Kodiaq Prestige 1,5 TSI mHEV 150 PS DSG | K23: 1
B24: Scala | C24: Yeni Scala Elite 1,0 TSI 115 PS DSG | D24: 60 | I24: Yeni Octavia | J24: Yeni Octavia Premium 1,5 TSI mHEV 150 PS DSG | K24: 326
B25: Yeni Octavia | C25: Yeni Octavia Premium 1,5 TSI mHEV 150 PS DSG | D25: 115 | I25: Yeni Superb | J25: Superb (Diğer) | K25: 94
B26: Yeni Superb | C26: Superb (Diğer) | D26: 60 | I26: Yeni Superb | J26: Yeni Superb Laurin & Klement Crystal 1,5 TSI mHEV 150 PS DSG | K26: 9
B27: Yeni Superb | C27: Yeni Superb Laurin & Klement Crystal 1,5 TSI mHEV 150 PS DSG | D27: 63 | I27: Yeni Superb | J27: Yeni Superb Premium 1,5 TSI mHEV 150 PS DSG | K27: 36
B28: Yeni Superb | C28: Yeni Superb Premium 1,5 TSI mHEV 150 PS DSG | D28: 292 | I28: Yeni Superb | J28: Yeni Superb Prestige 1,5 TSI mHEV 150 PS DSG | K28: 26
B29: Yeni Superb | C29: Yeni Superb Prestige 1,5 TSI mHEV 150 PS DSG | D29: 202
